Workbook

Sheet 조서별 규칙
A1: 섹션 | B1: 조서코드 | C1: 조서명 | D1: 단계 | E1: 갱신유형 | F1: 적용 | G1: 적용조건 · 메모 | H1: 시스템이 하는 일 | I1: 근거(명진 FY25 실물) | J1: 확신 | K1: 수정의견 ✏️ | L1: 반영 내역(09-26)
A2: 공통 | B2: 표지 | C2: 감사조서철 작성 및 보존 | D2: 공통 | E2: ① | F2: 항상 | H2: 이월본 그대로 · 머리만 링크로 | I2: 앞 3장 중 첫 장 | J2: 높음
A3: 공통 | B3: 표지 | C3: 조서표지(공통사항) | D3: 공통 | E3: 시스템 | F3: 항상 | G3: 회사명·결산일·대상기간·감사보고서일을 작업 건에서 채움 | H3: 시스템이 채움 | I3: B14~B17 | J3: 높음
A4: 공통 | B4: 목록 | C4: 조서목록 | D4: 공통 | E4: 시스템 | F4: 항상 | G4: 수행여부·작성자·작성일을 화면에서 받아 써 넣음 — 날짜의 정본. 각 조서 머리는 링크로 따라감 | H4: 시스템이 채움 | I4: D열 작성자 · E열 작성일 | J4: 높음
A5: 1000 감사계약 | B5: 1100 | C5: 계약전 위험평가 및 업무조건의 합의 | D5: 계획 | E5: ① | F5: 항상 | G5: ERP 에서 평가를 마친 조서 — 본문에 「ERP 에서 수행함」으로 적는다 | H5: ERP 수행 문구를 넣고 그대로 | I5: 머리 2025-04-14 · 값 26칸 | J5: 높음 | K5: erp평가를 마친 상태이며 erp에서 기재했다고 적어야 함. 즉 해당 일반조서작성은 erp 환경에서 기수행됨. | L5: ✓ 수정의견: ERP 에서 기수행
A6: 1000 감사계약 | B6: 1100A | C6: 계약전 위험평가표(수임) | D6: 계획 | E6: ① | F6: 조건부 | G6: 신규 수임(초도)일 때 · ERP 에서 평가를 마친 조서 — 본문에 「ERP 에서 수행함」으로 적는다 | H6: ERP 수행 문구를 넣고 그대로 | I6: 숨김 · 값 805칸 | J6: 높음 | K6: erp평가를 마친 상태이며 erp에서 기재했다고 적어야 함. 즉 해당 일반조서작성은 erp 환경에서 기수행됨. | L6: ✓ 수정의견: ERP 에서 기수행
A7: 1000 감사계약 | B7: 1200 | C7: 독립성, 윤리규정 및 품질관리기준의 준수 | D7: 계획 | E7: ① | F7: 항상 | G7: ERP 에서 평가를 마친 조서 — 본문에 「ERP 에서 수행함」으로 적는다 | H7: ERP 수행 문구를 넣고 그대로 | I7: 머리 2025-04-14 · 값 9칸 | J7: 높음 | K7: erp평가를 마친 상태이며 erp에서 기재했다고 적어야 함. 즉 해당 일반조서작성은 erp 환경에서 기수행됨. | L7: ✓ 수정의견: ERP 에서 기수행
A8: 1000 감사계약 | B8: 1300C | C8: 산업전문가 검토 | D8: 계획 | E8: ① | F8: 조건부 | G8: K-IFRS 적용기업에만 | H8: 이월본 그대로 · 머리만 링크로 | I8: 명진에 없음 | J8: 높음 | K8: 산업전문가는 K-IFRS 적용기업에만 해당함 | L8: ✓ 수정의견: K-IFRS 에만
A9: 2000 위험평가 | B9: 2100 | C9: 기업과 기업 환경에 대한 이해 | D9: 계획 | E9: ④ | F9: 항상 | G9: ★ 초안 도움 대상 — 전기 내용 + 거래처 정보 | H9: 전기 내용 보존 · 당기를 덧붙일 자리 표시 | I9: 머리 2025-04-14 · 값 28칸 | J9: 중간
A10: 2000 위험평가 | B10: 2100A | C10: 회사의 사업 및 법규에 대한 이해요약표 | D10: 계획 | E10: ④ | F10: 항상 | G10: ★ 초안 도움 대상 | H10: 전기 내용 보존 · 당기를 덧붙일 자리 표시 | I10: 값 197칸(서술) | J10: 중간
A11: 2000 위험평가 | B11: 2110 | C11: 감사계획의 수립 | D11: 계획 | E11: ② | F11: 항상 | G11: 일정·투입인력·감사팀 구성 | H11: 이월본 + 본문의 날짜·담당자 칸을 확인 목록으로 | I11: 값 39칸 | J11: 높음
A12: 2000 위험평가 | B12: 2110-1 | C12: 감사전략계획서(ASM) | D12: 계획 | E12: ② | F12: 항상 | G12: 별도 파일(docx) — Audit Lobby 에 따로 올림 | H12: 이월본 + 본문의 날짜·담당자 칸을 확인 목록으로 | I12: AuditLobby 폴더에 docx | J12: 높음
A13: 2000 위험평가 | B13: 2110-2 | C13: 계약후 감사위험 재평가 | D13: 계획 | E13: ① | F13: 항상 | G13: 특이사항이 없으면 그대로 · 예외: 초도, 전기 감사인 변경 | H13: 이월본 그대로 · 머리만 링크로 | I13: 값 75칸 | J13: 높음 | K13: 답이 거의 매년 같음. 즉 특이사항 발생하지 않는한 동의함(초도 전기외감인 회사 정도?) | L13: ✓ 수정의견: 매년 같음 동의
A14: 2000 위험평가 | B14: 2110A | C14: 업무분장표 | D14: 계획 | E14: ② | F14: 항상 | G14: 감사팀 구성·담당 | H14: 이월본 + 본문의 날짜·담당자 칸을 확인 목록으로 | I14: 값 182칸 | J14: 높음
A15: 2000 위험평가 | B15: 2120 | C15: 분석적절차(계획단계) | D15: 계획 | E15: ② | F15: 항상 | G15: 결론 문장 — 2120A 를 링크로 건다 | H15: 2120A 링크를 걸고 날짜·담당자 확인 | I15: 값 6칸 | J15: 높음 | K15: [2120A]조서를 링크로 걸어야함 | L15: ✓ 수정의견: 2120A 링크
A16: 2000 위험평가 | B16: 2120A | C16: 계획단계 분석적검토 | D16: 계획 | E16: ③ | F16: 항상 | G16: 당기 가결산 숫자 · 2차 화면 입력 후보 | H16: 전기를 틀로 두고 「당기 작성」 표시 | I16: 값 1,053칸(숫자) | J16: 높음
A17: 2000 위험평가 | B17: 2131 | C17: 감사인측 전문가의 활용 | D17: 계획 | E17: ① | F17: 항상 | G17: 보통 「해당없음」 | H17: 이월본 그대로 · 머리만 링크로 | I17: 값 13칸 | J17: 높음
A18: 2000 위험평가 | B18: 2301 | C18: 감사위험의 평가 | D18: 계획 | E18: ① | F18: 항상 | G18: 보통 그대로 · 일관성 점검 대상 — 2301·2302·2530·3100·3150 이 서로 맞아야 함 | H18: 이월본 그대로 + 일관성 점검 | I18: 값 54칸 | J18: 높음 | L18: ✓ 대화 안내: 보통 그대로, 상호 대사
A19: 2000 위험평가 | B19: 2302 | C19: 중요왜곡표시위험의 식별·평가 및 대응 | D19: 계획 | E19: ① | F19: 항상 | G19: 기본 세팅: 유의적 위험 = 부정위험·매출. 계정 잔액만 당기 숫자 · 일관성 점검 대상 — 2301·2302·2530·3100·3150 이 서로 맞아야 함 | H19: 이월본 그대로 + 일관성 점검 | I19: 값 553칸 | J19: 높음 | L19: ✓ 대화 안내: 보통 그대로, 유의적 위험 기본 세팅
A20: 2000 위험평가 | B20: 2511 | C20: 통제환경 이해와 평가 | D20: 계획 | E20: ① | F20: 항상 | G20: ★ 초안 도움 — 비상장은 채우기 어려운 자리 | H20: 이월본 그대로 · 머리만 링크로 | I20: 값 91칸 | J20: 중간
A21: 2000 위험평가 | B21: 2512 | C21: 위험평가절차 이해와 평가 | D21: 계획 | E21: ① | F21: 항상 | G21: ★ 초안 도움 | H21: 이월본 그대로 · 머리만 링크로 | I21: 값 43칸 | J21: 중간
A22: 2000 위험평가 | B22: 2513 | C22: 통제의 모니터링 이해와 평가 | D22: 계획 | E22: ① | F22: 항상 | G22: ★ 초안 도움 | H22: 이월본 그대로 · 머리만 링크로 | I22: 값 42칸 | J22: 중간
A23: 2000 위험평가 | B23: 2520 | C23: 정보시스템과 커뮤니케이션의 이해와 평가 | D23: 계획 | E23: ① | F23: 항상 | G23: ★ 초안 도움(IT) | H23: 이월본 그대로 · 머리만 링크로 | I23: 값 191칸 | J23: 중간
A24: 2000 위험평가 | B24: 2530 | C24: 통제활동의 이해와 평가·통제 test | D24: 계획 | E24: ① | F24: 항상 | G24: 비상장은 통제테스트를 하지 않음 — 이해·평가만 · 일관성 점검 대상 — 2301·2302·2530·3100·3150 이 서로 맞아야 함 | H24: 이월본 그대로 + 일관성 점검 | I24: 값 280칸 | J24: 높음 | L24: ✓ 대화 안내: 비상장은 통제테스트 안 함
A25: 2000 위험평가 | B25: 2531 | C25: 통제활동 이해·평가·미비점(소규모) | D25: 계획 | E25: ① | F25: 조건부 | G25: 소규모감사기준일 때 | H25: 이월본 그대로 · 머리만 링크로 | I25: 숨김(소규모 쌍) | J25: 중간
A26: 2000 위험평가 | B26: 2532 | C26: 정보기술(IT)시스템과 IT일반통제(소규모) | D26: 계획 | E26: ① | F26: 조건부 | G26: 소규모감사기준일 때 · ★ 초안 도움(IT) | H26: 이월본 그대로 · 머리만 링크로 | I26: 숨김(소규모 쌍) | J26: 중간
A27: 2000 위험평가 | B27: 2600 | C27: 내부회계관리제도 검토 | D27: 계획 | E27: ④ | F27: 조건부 | G27: 상장회사가 아니면 해당없음 | H27: 전기 내용 보존 · 당기를 덧붙일 자리 표시 | I27: 명진에 없음 | J27: 높음 | K27: 대부분 상장회사가 아니면 해당 없음 | L27: ✓ 수정의견: 상장 아니면 해당없음
A28: 2000 위험평가 | B28: 2700 | C28: 중요성 | D28: 계획·중간·기말 | E28: ③ | F28: 항상 | G28: 세 번 다시 씀 — 최종 날짜는 기말 | H28: 전기를 틀로 두고 「당기 작성」 표시 | I28: 값 28칸 | J28: 높음
A29: 2000 위험평가 | B29: 2700A | C29: 중요성 요약표 | D29: 계획·중간·기말 | E29: ③ | F29: 항상 | G29: 세 단계 결과를 한 표에 | H29: 전기를 틀로 두고 「당기 작성」 표시 | I29: 값 47칸 | J29: 높음
A30: 2000 위험평가 | B30: 2700A-1 | C30: 중요성 산정(감사계획단계) | D30: 계획 | E30: ③ | F30: 항상 | G30: 2차 화면 입력 후보 | H30: 전기를 틀로 두고 「당기 작성」 표시 | I30: 머리 2025-04-14 | J30: 높음
A31: 2000 위험평가 | B31: 2700A-2 | C31: 중요성 산정(감사수행단계) | D31: 중간 | E31: ③ | F31: 항상 | H31: 전기를 틀로 두고 「당기 작성」 표시 | I31: 머리 2026-03-23 — 중간 것을 기말에 적음 | J31: 높음
A32: 2000 위험평가 | B32: 2700A-3 | C32: 중요성 산정(감사완결단계) | D32: 기말 | E32: ③ | F32: 항상 | H32: 전기를 틀로 두고 「당기 작성」 표시 | I32: 머리 2026-03-23 | J32: 높음
A33: 2000 위험평가 | B33: 2700A-1(적용지침) | C33: 중요성 산정 적용지침 | D33: — | E33: 참고 | F33: 항상 | G33: 작성 대상 아님 | H33: 손대지 않음 | I33: 머리 없음 | J33: 높음
A34: 2000 위험평가 | B34: 참고_2700 | C34: 중요성 벤치마크 사례 | D34: — | E34: 참고 | F34: 항상 | G34: 작성 대상 아님 | H34: 손대지 않음 | I34: 값 0칸 | J34: 높음
A35: 3000 위험대응 | B35: 3100 | C35: 위험에 대한 대응 | D35: 중간 | E35: ① | F35: 항상 | G35: 기본 세팅: 실증절차 위주 · 통제테스트 안 함 · 기말에 테스트 범위 확대. 회사 특화 문구만 손봄 · 일관성 점검 대상 — 2301·2302·2530·3100·3150 이 서로 맞아야 함 | H35: 이월본 그대로 + 일관성 점검 | I35: 머리 2025-12-26 · 값 475칸 | J35: 높음 | L35: ✓ 대화 안내: 보통 그대로, 실증 위주
A36: 3000 위험대응 | B36: 3150 | C36: 통제테스트 | D36: 중간 | E36: ③ | F36: 조건부 | G36: 통제에 의존할 때 — 비상장 기본은 해당없음 · 일관성 점검 대상 — 2301·2302·2530·3100·3150 이 서로 맞아야 함 | H36: 전기를 틀로 두고 「당기 작성」 표시 | I36: 숨김 | J36: 높음 | L36: ✓ 대화 안내: 통제테스트 안 함
A37: 3000 위험대응 | B37: 3200 | C37: 유의적 사항에 대한 문서화 | D37: 중간 | E37: ③ | F37: 항상 | G37: 당기 유의적 사항 | H37: 전기를 틀로 두고 「당기 작성」 표시 | I37: 머리 2025-12-26 · 값 28칸 | J37: 중간
A38: 3000 위험대응 | B38: 3300 | C38: 분석적절차(수행단계) | D38: 중간 | E38: ③ | F38: 항상 | H38: 전기를 틀로 두고 「당기 작성」 표시 | I38: 머리 2025-12-26 · 값 10칸 | J38: 높음
A39: 3000 위험대응 | B39: 3300A | C39: 실증적 분석절차 | D39: 중간 | E39: ③ | F39: 조건부 | G39: 실증분석을 쓸 때 | H39: 전기를 틀로 두고 「당기 작성」 표시 | I39: 숨김 | J39: 중간
A40: 3000 위험대응 | B40: 3400 | C40: 공정가치 등 회계추정치 | D40: 중간 | E40: ④ | F40: 항상 | G40: 추정치 목록은 이월, 당기 평가 | H40: 전기 내용 보존 · 당기를 덧붙일 자리 표시 | I40: 머리 2025-12-26 · 값 78칸 | J40: 중간
...

Sheet 범례
A1: 일반조서 조서별 규칙 — 초안(2026-09-25)
A3: 고쳐 주실 곳 | B3: 「조서별 규칙」의 노란 칸(수정의견)에 적거나, 갱신유형·단계 칸을 바로 바꾸셔도 됩니다(목록에서 고름).
A4: 수정의견 예시 | B4: ② → ④ · 매년 특수관계자 표를 새로 덧붙임 | C4: ← 이런 식으로 짧게
A6: 갱신유형 | B6: 뜻 | C6: 시스템이 하는 일
A7: ① | B7: 그대로 — 내용이 매년 같고 머리(날짜·작성자)만 바뀐다 | C7: 이월본 그대로 · 머리만 링크로
A8: ② | B8: 날짜·담당자 — 본문의 날짜·사람 칸만 고친다 | C8: 이월본 + 본문의 날짜·담당자 칸을 확인 목록으로
A9: ③ | B9: 새로 작성 — 당기 숫자·판단을 새로 적는다 | C9: 전기를 틀로 두고 「당기 작성」 표시
A10: ④ | B10: 누적 — 전기 내용을 남기고 당기를 덧붙인다 | C10: 전기 내용 보존 · 당기를 덧붙일 자리 표시
A11: 참고 | B11: 작성 대상이 아닌 안내·예시 시트 | C11: 손대지 않음
A12: 첨부 | B12: 시트가 아니라 파일(시산표·재무제표·보고서) | C12: 파일 자리만 — 올리면 묶음에 넣음
A13: 시스템 | B13: 표지·조서목록 — 작업 건 정보로 채운다 | C13: 시스템이 채움
A15: 단계 | B15: 근거 — 명진 FY25 조서 머리의 작성일
A16: 계획 | B16: 2025-04-14 — 1000·2000 전부, 8500 별첨1 | C16: 보통 4~5월
A17: 중간 | B17: 2025-12-26 — 3100·3200·3300·3400 | C17: 중간감사
A18: 기말 | B18: 2026-03-23 — 3500·3600·3700·8000 전부, 2700A-2·3 | C18: 보고서 발행 때
A20: 정해진 것 | B20: 검토자(파트너) = 작업 건마다 기록 · 지금은 전 회사 조현규 | C20: 2026-09-25 사용자
B21: 작성자 기본값 = 그 회사 감사 매출계약의 담당회계사(18곳 중 17곳 정우철, 에스씨티 김준성). 조서마다 바꿀 수 있음 | C21: 2026-09-25 사용자
B22: 날짜 = 손으로 적는다(타임리포트 근거, 나중에 일괄 기입 가능) | C22: 2026-09-25 사용자
B23: ★ 초안 도움 대상 = 회사 사업 이해(2100·2100A)와 내부통제·IT(2511~2532·2600)
A25: 일관성 규칙 | B25: 위험평가 → 대응이 서로 맞아야 한다(사용자 안내 2026-09-26). 비상장 기본 세팅:
A26: 2302 | B26: 유의적 위험 = 부정위험 · 매출(수익인식). 이 기본에서 벗어나는 회사는 거의 없다
A27: 2530 · 3150 | B27: 통제테스트를 하지 않는다 — 통제는 이해·평가만
A28: 3100 | B28: 실증절차 위주 · 통제위험에 대응해 기말에 테스트 범위를 넓힌다 · 회사 특화 문구만 손본다
A29: 시스템 | B29: 다섯 조서의 선택이 어긋나면 이월 때 경고로 띄운다
A31: 샘플 기준 | B31: 명진산업개발 FY2025 조서는 「소규모감사기준」 양식이다(재무제표는 일반기업회계기준) | C31: 2026-09-26 사용자
A32: ERP 조서 | B32: 1100·1100A·1200 은 인덕 ERP 에서 평가를 마친다 — 조서엔 「ERP 에서 수행함」 | C32: 2026-09-26 사용자

Sheet 요약
A1: 단계 \ 갱신유형 | B1: ① | C1: ② | D1: ③ | E1: ④ | F1: 참고 | G1: 첨부 | H1: 합계
A2: 계획 | B2: =COUNTIFS('조서별 규칙'!$D$2:$D$72,"*계획*",'조서별 규칙'!$E$2:$E$72,"①") -> 15 | C2: =COUNTIFS('조서별 규칙'!$D$2:$D$72,"*계획*",'조서별 규칙'!$E$2:$E$72,"②") -> 5 | D2: =COUNTIFS('조서별 규칙'!$D$2:$D$72,"*계획*",'조서별 규칙'!$E$2:$E$72,"③") -> 4 | E2: =COUNTIFS('조서별 규칙'!$D$2:$D$72,"*계획*",'조서별 규칙'!$E$2:$E$72,"④") -> 3 | F2: =COUNTIFS('조서별 규칙'!$D$2:$D$72,"*계획*",'조서별 규칙'!$E$2:$E$72,"참고") -> 0 | G2: =COUNTIFS('조서별 규칙'!$D$2:$D$72,"*계획*",'조서별 규칙'!$E$2:$E$72,"첨부") -> 0 | H2: =SUM(B2:G2) -> 27
A3: 중간 | B3: =COUNTIFS('조서별 규칙'!$D$2:$D$72,"*중간*",'조서별 규칙'!$E$2:$E$72,"①") -> 1 | C3: =COUNTIFS('조서별 규칙'!$D$2:$D$72,"*중간*",'조서별 규칙'!$E$2:$E$72,"②") -> 0 | D3: =COUNTIFS('조서별 규칙'!$D$2:$D$72,"*중간*",'조서별 규칙'!$E$2:$E$72,"③") -> 7 | E3: =COUNTIFS('조서별 규칙'!$D$2:$D$72,"*중간*",'조서별 규칙'!$E$2:$E$72,"④") -> 1 | F3: =COUNTIFS('조서별 규칙'!$D$2:$D$72,"*중간*",'조서별 규칙'!$E$2:$E$72,"참고") -> 0 | G3: =COUNTIFS('조서별 규칙'!$D$2:$D$72,"*중간*",'조서별 규칙'!$E$2:$E$72,"첨부") -> 0 | H3: =SUM(B3:G3) -> 9
A4: 기말 | B4: =COUNTIFS('조서별 규칙'!$D$2:$D$72,"*기말*",'조서별 규칙'!$E$2:$E$72,"①") -> 2 | C4: =COUNTIFS('조서별 규칙'!$D$2:$D$72,"*기말*",'조서별 규칙'!$E$2:$E$72,"②") -> 11 | D4: =COUNTIFS('조서별 규칙'!$D$2:$D$72,"*기말*",'조서별 규칙'!$E$2:$E$72,"③") -> 11 | E4: =COUNTIFS('조서별 규칙'!$D$2:$D$72,"*기말*",'조서별 규칙'!$E$2:$E$72,"④") -> 4 | F4: =COUNTIFS('조서별 규칙'!$D$2:$D$72,"*기말*",'조서별 규칙'!$E$2:$E$72,"참고") -> 0 | G4: =COUNTIFS('조서별 규칙'!$D$2:$D$72,"*기말*",'조서별 규칙'!$E$2:$E$72,"첨부") -> 3 | H4: =SUM(B4:G4) -> 31
A5: 합계 | B5: =SUM(B2:B4) -> 18 | C5: =SUM(C2:C4) -> 16 | D5: =SUM(D2:D4) -> 22 | E5: =SUM(E2:E4) -> 8 | F5: =SUM(F2:F4) -> 0 | G5: =SUM(G2:G4) -> 3 | H5: =SUM(H2:H4) -> 67
A7: 사람 손이 드는 조서(③+④) | B7: =D5+E5 -> 30
A8: 시스템이 거의 끝내는 조서(①+②) | B8: =B5+C5 -> 34
A10: 주: 여러 단계에 걸친 조서(2700·2700A)는 각 단계에 한 번씩 셉니다. 적용 「조건부」도 포함한 숫자입니다.
